Workbook

Sheet Scaled Feature Values
A1: KNN – Standardized Feature Values (Test Instance & Top 10 Neighbours)
B2: Instance | C2: Pregnancies | D2: Glucose | E2: BloodPressure | F2: SkinThickness | G2: Insulin | H2: BMI | I2: DiabetesPedigreeFunction | J2: Age | K2: True Label
A3: # | B3: TEST | C3: 0.6399 | D3: -0.7777 | E3: -1.1901 | F3: 0.443 | G3: 0.5714 | H3: 0.2248 | I3: -0.1265 | J3: 0.8304 | K3: Non-diabetic (0)
A4: 1 | B4: Train [226] | C4: 0.6399 | D4: -0.2188 | E4: -1.0246 | F4: 1.1259 | G4: -0.1815 | H4: 0.1812 | I4: -0.6852 | J4: 0.5751 | K4: Diabetic (1)
A5: 2 | B5: Train [521] | C5: 0.9369 | D5: -0.2517 | E5: -0.5283 | F5: -0.0123 | G5: -0.1815 | H5: 0.0502 | I5: -0.6459 | J5: 0.7453 | K5: Diabetic (1)
A6: 3 | B6: Train [403] | C6: 0.6399 | D6: -0.9749 | E6: -0.8592 | F6: 0.3292 | G6: -0.17 | H6: -0.0663 | I6: -1.1684 | J6: 1.0856 | K6: Non-diabetic (0)
A7: 4 | B7: Train [430] | C7: 0.343 | D7: -0.2847 | E7: -0.192 | F7: 0.2156 | G7: -0.1815 | H7: 0.1376 | I7: -0.4559 | J7: 0.5751 | K7: Diabetic (1)
A8: 5 | B8: Train [321] | C8: 0.6399 | D8: -0.4823 | E8: -0.692 | F8: 0.6696 | G8: 0.5714 | H8: 0.471 | I8: -0.3553 | J8: 0.5751 | K8: Diabetic (1)
A9: 6 | B9: Train [90] | C9: 0.6399 | D9: -0.4823 | E9: -0.3556 | F9: 0.443 | G9: 0.5714 | H9: 0.6581 | I9: -0.8754 | J9: 0.43 | K9: Non-diabetic (0)
A10: 7 | B10: Train [18] | C10: 0.343 | D10: -0.613 | E10: -0.3556 | F10: 0.5563 | G10: -0.207 | H10: 0.3565 | I10: -0.8037 | J10: 0.5751 | K10: Diabetic (1)
A11: 8 | B11: Train [213] | C11: 0.6399 | D11: -0.3516 | E11: -0.5283 | F11: 0.6696 | G11: -0.1815 | H11: 0.4284 | I11: -0.2546 | J11: 1.0856 | K11: Non-diabetic (0)
A12: 9 | B12: Train [260] | C12: 0.6399 | D12: -0.9091 | E12: -1.1901 | F12: 0.443 | G12: 0.5714 | H12: 0.3565 | I12: -0.5841 | J12: 0.7453 | K12: Non-diabetic (0)
A13: 10 | B13: Train [412] | C13: 0.6399 | D13: -0.5152 | E13: -0.5283 | F13: 0.443 | G13: -0.056 | H13: 0.094 | I13: -0.5841 | J13: 1.0856 | K13: Diabetic (1)

Sheet Step-by-Step Computation
A1: Manual Euclidean Distance Computation – Step by Step
A2: Test Instance: Pregnancies=0.6399 Glucose=−0.7777 BloodPressure=−1.1901 SkinThickness=0.4430 Insulin=0.5714 BMI=0.2248 DiabPedigree=−0.1265 Age=0.8304
A3: Neighbour | B3: Feature | C3: Test (pᵢ) | D3: Train (qᵢ) | E3: pᵢ − qᵢ | F3: (pᵢ − qᵢ)²
A4: #1 Train[226] | B4: Pregnancies | C4: ='Scaled Feature Values'!C3 -> 0.6399 | D4: ='Scaled Feature Values'!C4 -> 0.6399 | E4: =C4-D4 -> 0 | F4: =E4^2 -> 0
B5: Glucose | C5: ='Scaled Feature Values'!D3 -> -0.7777 | D5: ='Scaled Feature Values'!D4 -> -0.2188 | E5: =C5-D5 -> -0.5589 | F5: =E5^2 -> 0.31236921
B6: BloodPressure | C6: ='Scaled Feature Values'!E3 -> -1.1901 | D6: ='Scaled Feature Values'!E4 -> -1.0246 | E6: =C6-D6 -> -0.1655 | F6: =E6^2 -> 0.02739025
B7: SkinThickness | C7: ='Scaled Feature Values'!F3 -> 0.443 | D7: ='Scaled Feature Values'!F4 -> 1.1259 | E7: =C7-D7 -> -0.6829 | F7: =E7^2 -> 0.46635241
B8: Insulin | C8: ='Scaled Feature Values'!G3 -> 0.5714 | D8: ='Scaled Feature Values'!G4 -> -0.1815 | E8: =C8-D8 -> 0.7529 | F8: =E8^2 -> 0.56685841
B9: BMI | C9: ='Scaled Feature Values'!H3 -> 0.2248 | D9: ='Scaled Feature Values'!H4 -> 0.1812 | E9: =C9-D9 -> 0.0436 | F9: =E9^2 -> 0.00190096
B10: DiabetesPedigreeFunction | C10: ='Scaled Feature Values'!I3 -> -0.1265 | D10: ='Scaled Feature Values'!I4 -> -0.6852 | E10: =C10-D10 -> 0.5587 | F10: =E10^2 -> 0.31214569
B11: Age | C11: ='Scaled Feature Values'!J3 -> 0.8304 | D11: ='Scaled Feature Values'!J4 -> 0.5751 | E11: =C11-D11 -> 0.2553 | F11: =E11^2 -> 0.06517809
A12: Sum of Squared Differences → | F12: =SUM(F4:F11) -> 1.752195
A13: d = √(sum) → Euclidean Distance to #1 Train[226] | F13: =SQRT(F12) -> 1.323705
A15: #2 Train[521] | B15: Pregnancies | C15: ='Scaled Feature Values'!C3 -> 0.6399 | D15: ='Scaled Feature Values'!C5 -> 0.9369 | E15: =C15-D15 -> -0.297 | F15: =E15^2 -> 0.088209
B16: Glucose | C16: ='Scaled Feature Values'!D3 -> -0.7777 | D16: ='Scaled Feature Values'!D5 -> -0.2517 | E16: =C16-D16 -> -0.526 | F16: =E16^2 -> 0.276676
B17: BloodPressure | C17: ='Scaled Feature Values'!E3 -> -1.1901 | D17: ='Scaled Feature Values'!E5 -> -0.5283 | E17: =C17-D17 -> -0.6618 | F17: =E17^2 -> 0.43797924
B18: SkinThickness | C18: ='Scaled Feature Values'!F3 -> 0.443 | D18: ='Scaled Feature Values'!F5 -> -0.0123 | E18: =C18-D18 -> 0.4553 | F18: =E18^2 -> 0.20729809
B19: Insulin | C19: ='Scaled Feature Values'!G3 -> 0.5714 | D19: ='Scaled Feature Values'!G5 -> -0.1815 | E19: =C19-D19 -> 0.7529 | F19: =E19^2 -> 0.56685841
B20: BMI | C20: ='Scaled Feature Values'!H3 -> 0.2248 | D20: ='Scaled Feature Values'!H5 -> 0.0502 | E20: =C20-D20 -> 0.1746 | F20: =E20^2 -> 0.03048516
B21: DiabetesPedigreeFunction | C21: ='Scaled Feature Values'!I3 -> -0.1265 | D21: ='Scaled Feature Values'!I5 -> -0.6459 | E21: =C21-D21 -> 0.5194 | F21: =E21^2 -> 0.26977636
B22: Age | C22: ='Scaled Feature Values'!J3 -> 0.8304 | D22: ='Scaled Feature Values'!J5 -> 0.7453 | E22: =C22-D22 -> 0.0851 | F22: =E22^2 -> 0.00724201
A23: Sum of Squared Differences → | F23: =SUM(F15:F22) -> 1.8845243
A24: d = √(sum) → Euclidean Distance to #2 Train[521] | F24: =SQRT(F23) -> 1.3727798
A26: #3 Train[403] | B26: Pregnancies | C26: ='Scaled Feature Values'!C3 -> 0.6399 | D26: ='Scaled Feature Values'!C6 -> 0.6399 | E26: =C26-D26 -> 0 | F26: =E26^2 -> 0
B27: Glucose | C27: ='Scaled Feature Values'!D3 -> -0.7777 | D27: ='Scaled Feature Values'!D6 -> -0.9749 | E27: =C27-D27 -> 0.1972 | F27: =E27^2 -> 0.03888784
B28: BloodPressure | C28: ='Scaled Feature Values'!E3 -> -1.1901 | D28: ='Scaled Feature Values'!E6 -> -0.8592 | E28: =C28-D28 -> -0.3309 | F28: =E28^2 -> 0.10949481
B29: SkinThickness | C29: ='Scaled Feature Values'!F3 -> 0.443 | D29: ='Scaled Feature Values'!F6 -> 0.3292 | E29: =C29-D29 -> 0.1138 | F29: =E29^2 -> 0.01295044
B30: Insulin | C30: ='Scaled Feature Values'!G3 -> 0.5714 | D30: ='Scaled Feature Values'!G6 -> -0.17 | E30: =C30-D30 -> 0.7414 | F30: =E30^2 -> 0.54967396
B31: BMI | C31: ='Scaled Feature Values'!H3 -> 0.2248 | D31: ='Scaled Feature Values'!H6 -> -0.0663 | E31: =C31-D31 -> 0.2911 | F31: =E31^2 -> 0.08473921
B32: DiabetesPedigreeFunction | C32: ='Scaled Feature Values'!I3 -> -0.1265 | D32: ='Scaled Feature Values'!I6 -> -1.1684 | E32: =C32-D32 -> 1.0419 | F32: =E32^2 -> 1.0855556
B33: Age | C33: ='Scaled Feature Values'!J3 -> 0.8304 | D33: ='Scaled Feature Values'!J6 -> 1.0856 | E33: =C33-D33 -> -0.2552 | F33: =E33^2 -> 0.06512704
A34: Sum of Squared Differences → | F34: =SUM(F26:F33) -> 1.9464289
A35: d = √(sum) → Euclidean Distance to #3 Train[403] | F35: =SQRT(F34) -> 1.3951448
A37: #4 Train[430] | B37: Pregnancies | C37: ='Scaled Feature Values'!C3 -> 0.6399 | D37: ='Scaled Feature Values'!C7 -> 0.343 | E37: =C37-D37 -> 0.2969 | F37: =E37^2 -> 0.08814961
B38: Glucose | C38: ='Scaled Feature Values'!D3 -> -0.7777 | D38: ='Scaled Feature Values'!D7 -> -0.2847 | E38: =C38-D38 -> -0.493 | F38: =E38^2 -> 0.243049
B39: BloodPressure | C39: ='Scaled Feature Values'!E3 -> -1.1901 | D39: ='Scaled Feature Values'!E7 -> -0.192 | E39: =C39-D39 -> -0.9981 | F39: =E39^2 -> 0.99620361
B40: SkinThickness | C40: ='Scaled Feature Values'!F3 -> 0.443 | D40: ='Scaled Feature Values'!F7 -> 0.2156 | E40: =C40-D40 -> 0.2274 | F40: =E40^2 -> 0.05171076
B41: Insulin | C41: ='Scaled Feature Values'!G3 -> 0.5714 | D41: ='Scaled Feature Values'!G7 -> -0.1815 | E41: =C41-D41 -> 0.7529 | F41: =E41^2 -> 0.56685841
B42: BMI | C42: ='Scaled Feature Values'!H3 -> 0.2248 | D42: ='Scaled Feature Values'!H7 -> 0.1376 | E42: =C42-D42 -> 0.0872 | F42: =E42^2 -> 0.00760384
B43: DiabetesPedigreeFunction | C43: ='Scaled Feature Values'!I3 -> -0.1265 | D43: ='Scaled Feature Values'!I7 -> -0.4559 | E43: =C43-D43 -> 0.3294 | F43: =E43^2 -> 0.10850436
...

Sheet Distance Summary
A1: KNN Distance Summary – Top 10 Nearest Neighbours
A2: Formula: d = √ [ Σ (pᵢ − qᵢ)² ] for i = 1…8 features | All values are Z-score standardized
A3: Rank | B3: Train Index | C3: Distance Formula (expanded) | D3: Distance
A4: 1 | B4: Train [226] | C4: √[ (0.6399−(0.6399))² + (−0.7777−(−0.2188))² + (−1.1901−(−1.0246))² + (0.4430−(1.1259))² + (0.5714−(−0.1815))² + (0.2248−(0.1812))² + (−0.1265−(−0.6852))² + (0.8304−(0.5751))² ] | D4: =SQRT((0.6399-(0.6399))^2+(-0.7777-(-0.2188))^2+(-1.1901-(-1.0246))^2+(0.443-(1.1259))^2+(0.5714-(-0.1815))^2+(0.2248-(0.1812))^2+(-0.1265-(-0.6852))^2+(0.8304-(0.5751))^2) -> 1.323705
A5: 2 | B5: Train [521] | C5: √[ (0.6399−(0.9369))² + (−0.7777−(−0.2517))² + (−1.1901−(−0.5283))² + (0.4430−(−0.0123))² + (0.5714−(−0.1815))² + (0.2248−(0.0502))² + (−0.1265−(−0.6459))² + (0.8304−(0.7453))² ] | D5: =SQRT((0.6399-(0.9369))^2+(-0.7777-(-0.2517))^2+(-1.1901-(-0.5283))^2+(0.443-(-0.0123))^2+(0.5714-(-0.1815))^2+(0.2248-(0.0502))^2+(-0.1265-(-0.6459))^2+(0.8304-(0.7453))^2) -> 1.3727798
A6: 3 | B6: Train [403] | C6: √[ (0.6399−(0.6399))² + (−0.7777−(−0.9749))² + (−1.1901−(−0.8592))² + (0.4430−(0.3292))² + (0.5714−(−0.1700))² + (0.2248−(−0.0663))² + (−0.1265−(−1.1684))² + (0.8304−(1.0856))² ] | D6: =SQRT((0.6399-(0.6399))^2+(-0.7777-(-0.9749))^2+(-1.1901-(-0.8592))^2+(0.443-(0.3292))^2+(0.5714-(-0.17))^2+(0.2248-(-0.0663))^2+(-0.1265-(-1.1684))^2+(0.8304-(1.0856))^2) -> 1.3951448
A7: 4 | B7: Train [430] | C7: √[ (0.6399−(0.3430))² + (−0.7777−(−0.2847))² + (−1.1901−(−0.1920))² + (0.4430−(0.2156))² + (0.5714−(−0.1815))² + (0.2248−(0.1376))² + (−0.1265−(−0.4559))² + (0.8304−(0.5751))² ] | D7: =SQRT((0.6399-(0.343))^2+(-0.7777-(-0.2847))^2+(-1.1901-(-0.192))^2+(0.443-(0.2156))^2+(0.5714-(-0.1815))^2+(0.2248-(0.1376))^2+(-0.1265-(-0.4559))^2+(0.8304-(0.5751))^2) -> 1.4585121
A8: 5 | B8: Train [321] | C8: √[ (0.6399−(0.6399))² + (−0.7777−(−0.4823))² + (−1.1901−(−0.6920))² + (0.4430−(0.6696))² + (0.5714−(0.5714))² + (0.2248−(0.4710))² + (−0.1265−(−0.3553))² + (0.8304−(0.5751))² ] | D8: =SQRT((0.6399-(0.6399))^2+(-0.7777-(-0.4823))^2+(-1.1901-(-0.692))^2+(0.443-(0.6696))^2+(0.5714-(0.5714))^2+(0.2248-(0.471))^2+(-0.1265-(-0.3553))^2+(0.8304-(0.5751))^2) -> 0.75156789
A9: 6 | B9: Train [90] | C9: √[ (0.6399−(0.6399))² + (−0.7777−(−0.4823))² + (−1.1901−(−0.3556))² + (0.4430−(0.4430))² + (0.5714−(0.5714))² + (0.2248−(0.6581))² + (−0.1265−(−0.8754))² + (0.8304−(0.4300))² ] | D9: =SQRT((0.6399-(0.6399))^2+(-0.7777-(-0.4823))^2+(-1.1901-(-0.3556))^2+(0.443-(0.443))^2+(0.5714-(0.5714))^2+(0.2248-(0.6581))^2+(-0.1265-(-0.8754))^2+(0.8304-(0.43))^2) -> 1.3009887
A10: 7 | B10: Train [18] | C10: √[ (0.6399−(0.3430))² + (−0.7777−(−0.6130))² + (−1.1901−(−0.3556))² + (0.4430−(0.5563))² + (0.5714−(−0.2070))² + (0.2248−(0.3565))² + (−0.1265−(−0.8037))² + (0.8304−(0.5751))² ] | D10: =SQRT((0.6399-(0.343))^2+(-0.7777-(-0.613))^2+(-1.1901-(-0.3556))^2+(0.443-(0.5563))^2+(0.5714-(-0.207))^2+(0.2248-(0.3565))^2+(-0.1265-(-0.8037))^2+(0.8304-(0.5751))^2) -> 1.4041126
A11: 8 | B11: Train [213] | C11: √[ (0.6399−(0.6399))² + (−0.7777−(−0.3516))² + (−1.1901−(−0.5283))² + (0.4430−(0.6696))² + (0.5714−(−0.1815))² + (0.2248−(0.4284))² + (−0.1265−(−0.2546))² + (0.8304−(1.0856))² ] | D11: =SQRT((0.6399-(0.6399))^2+(-0.7777-(-0.3516))^2+(-1.1901-(-0.5283))^2+(0.443-(0.6696))^2+(0.5714-(-0.1815))^2+(0.2248-(0.4284))^2+(-0.1265-(-0.2546))^2+(0.8304-(1.0856))^2) -> 1.1665059
A12: 9 | B12: Train [260] | C12: √[ (0.6399−(0.6399))² + (−0.7777−(−0.9091))² + (−1.1901−(−1.1901))² + (0.4430−(0.4430))² + (0.5714−(0.5714))² + (0.2248−(0.3565))² + (−0.1265−(−0.5841))² + (0.8304−(0.7453))² ] | D12: =SQRT((0.6399-(0.6399))^2+(-0.7777-(-0.9091))^2+(-1.1901-(-1.1901))^2+(0.443-(0.443))^2+(0.5714-(0.5714))^2+(0.2248-(0.3565))^2+(-0.1265-(-0.5841))^2+(0.8304-(0.7453))^2) -> 0.50124906
A13: 10 | B13: Train [412] | C13: √[ (0.6399−(0.6399))² + (−0.7777−(−0.5152))² + (−1.1901−(−0.5283))² + (0.4430−(0.4430))² + (0.5714−(−0.0560))² + (0.2248−(0.0940))² + (−0.1265−(−0.5841))² + (0.8304−(1.0856))² ] | D13: =SQRT((0.6399-(0.6399))^2+(-0.7777-(-0.5152))^2+(-1.1901-(-0.5283))^2+(0.443-(0.443))^2+(0.5714-(-0.056))^2+(0.2248-(0.094))^2+(-0.1265-(-0.5841))^2+(0.8304-(1.0856))^2) -> 1.0918561
A15: K=3 Vote: Neighbour #1 → Diabetic | Neighbour #2 → Diabetic | Neighbour #3 → Non-diabetic ➜ Majority = DIABETIC (1)

Sheet Model Accuracy (K=3,5,7)
A1: KNN Model Evaluation – Accuracy & Confusion Matrix
A2: K | B2: Accuracy (%) | C2: TN | D2: FP | E2: FN | F2: TP | G2: Precision | H2: Recall
A3: 3 | B3: =D3/(C3+D3+E3+F3) -> 0.16233766 | C3: 74 | D3: 25 | E3: 20 | F3: 35 | G3: =F3/(F3+D3) -> 0.58333333 | H3: =F3/(F3+E3) -> 0.63636364
A4: 5 | B4: =D4/(C4+D4+E4+F4) -> 0.15584416 | C4: 75 | D4: 24 | E4: 17 | F4: 38 | G4: =F4/(F4+D4) -> 0.61290323 | H4: =F4/(F4+E4) -> 0.69090909
A5: 7 | B5: =D5/(C5+D5+E5+F5) -> 0.16233766 | C5: 74 | D5: 25 | E5: 19 | F5: 36 | G5: =F5/(F5+D5) -> 0.59016393 | H5: =F5/(F5+E5) -> 0.65454545
A6: LR | B6: 0.7532 | C6: — | D6: — | E6: — | F6: — | G6: — | H6: —
